<?xml version="1.0" ?>

<robot name="kuka">
  <!-- Custom materials (colours) -->
  <material name="Black">
    <color rgba="0.2 0.2 0.2 1.0"/>
  </material>
  <material name="Blue">
    <color rgba="0.0 0.0 0.8 1.0"/>
  </material>
  <material name="Green">
    <color rgba="0.0 0.8 0.0 1.0"/>
  </material>
  <material name="TransGreen">
    <color rgba="0.0 0.8 0.0 0.0"/>
  </material>
  <material name="Grey">
    <color rgba="0.4 0.4 0.4 1.0"/>
  </material>

  <material name="Floor">
    <color rgba="0.5 0.5 0.5 1.0"/>
  </material>
  <material name="Red">
    <color rgba="0.8 0.0 0.0 1.0"/>
  </material>
  <material name="White">
    <color rgba="1.0 1.0 1.0 1.0"/>
  </material>
  <material name="Transparent">
    <color rgba="0.0 0.0 0.0 0.0"/>
  </material>

  <material name="Black">
    <color rgba="0.0 0.0 0.0 1.0"/>
  </material>
  <material name="Blue">
    <color rgba="0.0 0.0 0.8 1.0"/>
  </material>
  <material name="Green">
    <color rgba="0.0 0.8 0.0 1.0"/>
  </material>
  <material name="Grey">
    <color rgba="0.4 0.4 0.4 1.0"/>
  </material>
  <material name="Orange">
    <color rgba="1.0 0.423529411765 0.0392156862745 1.0"/>
  </material>
  <material name="Brown">
    <color rgba="0.870588235294 0.811764705882 0.764705882353 1.0"/>
  </material>
  <material name="Red">
    <color rgba="0.8 0.0 0.0 1.0"/>
  </material>
  <material name="White">
    <color rgba="1.0 1.0 1.0 1.0"/>
  </material>

  <link name="iiwa7_link_0">
    <inertial>
      <origin rpy="0 0 0" xyz="-0.1 0 0.07"/>
      <mass value="5"/>
      <inertia ixx="0.05" ixy="0" ixz="0" iyy="0.06" iyz="0" izz="0.03"/>
    </inertial>
    <visual>
      <origin rpy="0 0 0" xyz="0 0 0"/>
      <geometry>
        <mesh filename="../../urdf/kuka_openhand_description/meshes/iiwa7/visual/link_0.obj"/>
      </geometry>
      <material name="Grey"/>
    </visual>
    <collision>
      <origin rpy="0 0 0" xyz="0 0 0"/>
      <geometry>
        <mesh filename="../../urdf/kuka_openhand_description/meshes/iiwa7/collision/link_0.obj"/>
      </geometry>
      <material name="Grey"/>
    </collision>
    <self_collision_checking>
      <origin rpy="0 0 0" xyz="0 0 0"/>
      <geometry>
        <capsule length="0.25" radius="0.15"/>
      </geometry>
    </self_collision_checking>
  </link>
  <!-- joint between link_0 and link_1 -->
  <joint name="iiwa7_joint_1" type="revolute">
    <parent link="iiwa7_link_0"/>
    <child link="iiwa7_link_1"/>
    <origin rpy="0 0 0" xyz="0 0 0.15"/>
    <axis xyz="0 0 1"/>
    <limit effort="300" lower="-2.96705972839" upper="2.96705972839" velocity="10"/>
    <safety_controller k_position="100" k_velocity="2" soft_lower_limit="-2.93215314335" soft_upper_limit="2.93215314335"/>
    <dynamics damping="5.5" friction="0.025"/>
  </joint>
  <link name="iiwa7_link_1">
    <inertial>
      <origin rpy="0 0 0" xyz="0 -0.03 0.12"/>
      <mass value="3.4525"/>
      <inertia ixx="0.02183" ixy="0" ixz="0" iyy="0.007703" iyz="-0.003887" izz="0.02083"/>
    </inertial>
    <visual>
      <origin rpy="0 0 0" xyz="0 0 0.0075"/>
      <geometry>
        <mesh filename="../../urdf/kuka_openhand_description/meshes/iiwa7/visual/link_1.obj"/>
      </geometry>
      <material name="White"/>
    </visual>
    <collision>
      <origin rpy="0 0 0" xyz="0 0 0.0075"/>
      <geometry>
        <mesh filename="../../urdf/kuka_openhand_description/meshes/iiwa7/collision/link_1.obj"/>
      </geometry>
      <material name="White"/>
    </collision>
  </link>
  <joint name="iiwa7_joint_2" type="revolute">
    <parent link="iiwa7_link_1"/>
    <child link="iiwa7_link_2"/>
    <origin rpy="1.57079632679   0 3.14159265359" xyz="0 0 0.19"/>
    <axis xyz="0 0 1"/>
    <limit effort="300" lower="-2.09439510239" upper="2.09439510239" velocity="10"/>
    <safety_controller k_position="100" k_velocity="2" soft_lower_limit="-2.05948851735" soft_upper_limit="2.05948851735"/>
    <dynamics damping="5.55" friction="0.025"/>
  </joint>
  <link name="iiwa7_link_2">
    <inertial>
      <origin rpy="0 0 0" xyz="0.0003 0.059 0.042"/>
      <mass value="3.4821"/>
      <inertia ixx="0.02076" ixy="0" ixz="-0.003626" iyy="0.02179" iyz="0" izz="0.00779"/>
    </inertial>
    <visual>
      <origin rpy="0 0 0" xyz="0 0 0"/>
      <geometry>
        <mesh filename="../../urdf/kuka_openhand_description/meshes/iiwa7/visual/link_2.obj"/>
      </geometry>
      <material name="White"/>
    </visual>
    <collision>
      <origin rpy="0 0 0" xyz="0 0 0"/>
      <geometry>
        <mesh filename="../../urdf/kuka_openhand_description/meshes/iiwa7/collision/link_2.obj"/>
      </geometry>
      <material name="White"/>
    </collision>
  </link>
  <joint name="iiwa7_joint_3" type="revolute">
    <parent link="iiwa7_link_2"/>
    <child link="iiwa7_link_3"/>
    <origin rpy="1.57079632679 0 3.14159265359" xyz="0 0.21 0"/>
    <axis xyz="0 0 1"/>
    <limit effort="300" lower="-2.96705972839" upper="2.96705972839" velocity="10"/>
    <safety_controller k_position="100" k_velocity="2" soft_lower_limit="-2.93215314335" soft_upper_limit="2.93215314335"/>
    <dynamics damping="5.5" friction="0.025"/>
  </joint>
  <link name="iiwa7_link_3">
    <inertial>
      <origin rpy="0 0 0" xyz="0 0.03 0.13"/>
      <mass value="4.05623"/>
      <inertia ixx="0.03204" ixy="0" ixz="0" iyy="0.00972" iyz="0.006227" izz="0.03042"/>
    </inertial>
    <visual>
      <origin rpy="0 0 0" xyz="0 0 -0.026"/>
      <geometry>
        <mesh filename="../../urdf/kuka_openhand_description/meshes/iiwa7/visual/link_3.obj"/>
      </geometry>
      <material name="White"/>
    </visual>
    <collision>
      <origin rpy="0 0 0" xyz="0 0 -0.026"/>
      <geometry>
        <mesh filename="../../urdf/kuka_openhand_description/meshes/iiwa7/collision/link_3.obj"/>
      </geometry>
      <material name="White"/>
    </collision>
  </link>
  <joint name="iiwa7_joint_4" type="revolute">
    <parent link="iiwa7_link_3"/>
    <child link="iiwa7_link_4"/>
    <origin rpy="1.57079632679 0 0" xyz="0 0 0.19"/>
    <axis xyz="0 0 1"/>
    <limit effort="300" lower="-2.09439510239" upper="2.09439510239" velocity="10"/>
    <safety_controller k_position="100" k_velocity="2" soft_lower_limit="-2.05948851735" soft_upper_limit="2.05948851735"/>
    <dynamics damping="5.5" friction="0.025"/>
  </joint>
  <link name="iiwa7_link_4">
    <inertial>
      <origin rpy="0 0 0" xyz="0 0.067 0.034"/>
      <mass value="3.4822"/>
      <inertia ixx="0.02178" ixy="0" ixz="0" iyy="0.02075" iyz="-0.003625" izz="0.007785"/>
    </inertial>
    <visual>
      <origin rpy="0 0 0" xyz="0 0 0"/>
      <geometry>
        <mesh filename="../../urdf/kuka_openhand_description/meshes/iiwa7/visual/link_4.obj"/>
      </geometry>
      <material name="White"/>
    </visual>
    <collision>
      <origin rpy="0 0 0" xyz="0 0 0"/>
      <geometry>
        <mesh filename="../../urdf/kuka_openhand_description/meshes/iiwa7/collision/link_4.obj"/>
      </geometry>
      <material name="White"/>
    </collision>
  </link>
  <joint name="iiwa7_joint_5" type="revolute">
    <parent link="iiwa7_link_4"/>
    <child link="iiwa7_link_5"/>
    <origin rpy="-1.57079632679 3.14159265359 0" xyz="0 0.21 0"/>
    <axis xyz="0 0 1"/>
    <limit effort="300" lower="-2.96705972839" upper="2.96705972839" velocity="10"/>
    <safety_controller k_position="100" k_velocity="2" soft_lower_limit="-2.93215314335" soft_upper_limit="2.93215314335"/>
    <dynamics damping="5.5" friction="0.025"/>
  </joint>
  <link name="iiwa7_link_5">
    <inertial>
      <origin rpy="0 0 0" xyz="0.0001 0.021 0.076"/>
      <mass value="2.1633"/>
      <inertia ixx="0.01287" ixy="0" ixz="0" iyy="0.005708" iyz="-0.003946" izz="0.01112"/>
    </inertial>
    <visual>
      <origin rpy="0 0 0" xyz="0 0 -0.026"/>
      <geometry>
        <mesh filename="../../urdf/kuka_openhand_description/meshes/iiwa7/visual/link_5.obj"/>
      </geometry>
      <material name="White"/>
    </visual>
    <collision>
      <origin rpy="0 0 0" xyz="0 0 -0.026"/>
      <geometry>
        <mesh filename="../../urdf/kuka_openhand_description/meshes/iiwa7/collision/link_5.obj"/>
      </geometry>
      <material name="White"/>
    </collision>
  </link>
  <joint name="iiwa7_joint_6" type="revolute">
    <parent link="iiwa7_link_5"/>
    <child link="iiwa7_link_6"/>
    <origin rpy="1.57079632679 0 0" xyz="0 0.06070 0.19"/>
    <axis xyz="0 0 1"/>
    <limit effort="300" lower="-2.09439510239" upper="2.09439510239" velocity="10"/>
    <safety_controller k_position="100" k_velocity="2" soft_lower_limit="-2.05948851735" soft_upper_limit="2.05948851735"/>
    <dynamics damping="0.5" friction="0.025"/>
  </joint>
  <link name="iiwa7_link_6">
    <inertial>
      <origin rpy="0 0 0" xyz="0 0.0006 0.0004"/>
      <mass value="2.3466"/>
      <inertia ixx="0.006509" ixy="0" ixz="0" iyy="0.006259" iyz="0.00031891" izz="0.004527"/>
    </inertial>
    <visual>
      <origin rpy="0 0 0" xyz="0 0 0"/>
      <geometry>
        <mesh filename="../../urdf/kuka_openhand_description/meshes/iiwa7/visual/link_6.obj"/>
      </geometry>
      <material name="White"/>
    </visual>
    <collision>
      <origin rpy="0 0 0" xyz="0 0 0"/>
      <geometry>
        <mesh filename="../../urdf/kuka_openhand_description/meshes/iiwa7/collision/link_6.obj"/>
      </geometry>
      <material name="White"/>
    </collision>
  </link>
  <joint name="iiwa7_joint_7" type="revolute">
    <parent link="iiwa7_link_6"/>
    <child link="iiwa7_link_7"/>
    <origin rpy="-1.57079632679 3.14159265359 0" xyz="0 0.081 0.06070"/>
    <axis xyz="0 0 1"/>
    <limit effort="300" lower="-3.05432619099" upper="3.05432619099" velocity="10"/>
    <safety_controller k_position="100" k_velocity="2" soft_lower_limit="-3.01941960595" soft_upper_limit="3.01941960595"/>
    <dynamics damping="5.5" friction="0.025"/>
  </joint>
  <link name="iiwa7_link_7">
    <inertial>
      <origin rpy="0 0 0" xyz="0 0 0.02"/>
      <mass value="3.129"/>
      <inertia ixx="0.01464" ixy="0.0005912" ixz="0" iyy="0.01465" iyz="0" izz="0.002872"/>
    </inertial>
    <visual>
      <origin rpy="0 0 0" xyz="0 0 -0.0005"/>
      <geometry>
        <mesh filename="../../urdf/kuka_openhand_description/meshes/iiwa7/visual/link_7.obj"/>
      </geometry>
      <material name="Grey"/>
    </visual>
    <collision>
      <origin rpy="0 0 0" xyz="0 0 -0.0005"/>
      <geometry>
        <mesh filename="../../urdf/kuka_openhand_description/meshes/iiwa7/collision/link_7.obj"/>
      </geometry>
      <material name="Grey"/>
    </collision>
  </link>

  <!-- gripper tags -->

   <link name="dummy_ft">
    <visual>
      <geometry>
        <cylinder length="0.05" radius="0.05"/>
      </geometry>
      <material name="Grey"/>
    </visual>
    <inertial>
      <origin xyz="0 0 0" rpy="0 0 0"/>
      <mass value="0.1"/>
      <inertia ixx="0.001"  ixy="0"  ixz="0" iyy="0.001" iyz="0" izz="0.001" />
    </inertial>
    <collision>
      <origin xyz="0 0 0" rpy="0 0 0"/>
      <geometry>
        <cylinder length="0.05" radius="0.05"/>
      </geometry>
    </collision>
  </link>

  <!-- joint between link_ee and gripper -->
  <joint name="iiwa_ft_base_joint" type="fixed">
    <parent link="iiwa7_link_7"/>
    <child link="dummy_ft"/>
    <origin rpy="0 0 0" xyz="0 0 0.09"/>
  </joint>

  <joint name="iiwa_gripper_base_joint" type="fixed">
    <parent link="dummy_ft"/>
    <child link="gripper_base_link"/>
    <origin rpy="0 1.57079632679 0" xyz="0 0 0.085"/>
  </joint>

  <link name="gripper_base_link">
    <visual>
      <origin rpy="1.57079632679 0 -1.57079632679" xyz="0.06 0.017 0"/>
      <origin rpy="0 0 0" xyz="0 0 0"/>
      <geometry>
        <mesh filename="../../urdf/kuka_openhand_description/meshes/yale_openhand_O/base_link.obj"/>
      </geometry>
  <material name="coolgrey" >
    <color rgba="0.5843137254901961 0.6392156862745098 0.6509803921568628 1.0" />
  </material>
    </visual>
    <inertial>
      <origin rpy="0 0 0" xyz="0.03 0 0."/>
      <mass value="0.7"/>
      <inertia ixx="0.001" ixy="0.0" ixz="0.0" iyy="0.001" iyz="0.0" izz="0.001"/>
    </inertial>
    <collision>
      <origin rpy="1.57079632679 0 -1.57079632679" xyz="0.06 0.017 0"/>
      <geometry>
        <mesh filename="../../urdf/kuka_openhand_description/meshes/yale_openhand_O/base_link.obj"/>
      </geometry>
    </collision>
  </link>

  <link name="finger_1_1">
     <contact>
        <lateral_friction value="1"/>
        <rolling_friction value="0.1"/>
        <contact_cfm value="0.0"/>
        <contact_erp value="1.0"/>
      </contact>
    <inertial>
      <origin rpy="0 0 0" xyz="0 0 0"/>
      <mass value="0.1"/>
      <inertia ixx="0.001" ixy="0.0" ixz="0.0" iyy="0.001" iyz="0.0" izz="0.001"/>
    </inertial>
    <visual>
  <material name="coolgrey" >
    <color rgba="0.5843137254901961 0.6392156862745098 0.6509803921568628 1.0" />
  </material>
      <origin rpy="1.57079632679 3.14159265359 -1.57079632679" xyz="-0.00 0.0 0.00"/>
      <geometry>
        <!-- <cylinder length="0.002" radius="0.018" /> -->
        <mesh filename="../../urdf/kuka_openhand_description/meshes/yale_openhand_O/swivel_1.obj"/>
      </geometry>
    </visual>
    <collision>
      <origin rpy="0 1.57079632679 0 " xyz="0.00 0.0 0.00"/>
      <geometry>
        <cylinder length="0.002" radius="0.018"/>
      </geometry>
    </collision>
  </link>

  <link name="finger_1_2">
        <contact>
        <lateral_friction value="1"/>
        <rolling_friction value="0.1"/>
        <contact_cfm value="0.0"/>
        <contact_erp value="1.0"/>
      </contact>
    <inertial>
      <origin rpy="0 0 0" xyz="0 0 0"/>
      <mass value="0.1"/>
      <inertia ixx="0.001" ixy="0.0" ixz="0.0" iyy="0.001" iyz="0.0" izz="0.001"/>
    </inertial>
    <visual>
  <material name="lightgrey" >
    <color rgba="0.8470588235294118 0.8627450980392157 0.8392156862745098 1.0" />
  </material>
      <origin rpy="0 -3.141592653592 2.4" xyz="-0.00 0.0753 0.008"/>
      <geometry>
        <mesh filename="../../urdf/kuka_openhand_description/meshes/yale_openhand_O/proximal_O.obj" scale="0.00100 0.00100 0.00100"/>
      </geometry>
    </visual>
    <collision>
      <origin rpy="0 -3.141592653592 2.4" xyz="-0.00 0.0753 0.008"/>
      <geometry>
        <mesh filename="../../urdf/kuka_openhand_description/meshes/yale_openhand_O/proximal_O.obj" scale="0.00100 0.00100 0.00100"/>
      </geometry>
    </collision>
  </link>

  <link name="finger_1_3">
      <inertial>
      <!--                  <origin xyz="-0.005 0.03 0" rpy="0 0 0"/>-->
      <origin rpy="0 0 0" xyz="0 0 0"/>
      <mass value="0.1"/>
      <inertia ixx="0.001" ixy="0.0" ixz="0.0" iyy="0.001" iyz="0.0" izz="0.001"/>
    </inertial>
    <visual>
      <geometry>
        <mesh filename="../../urdf/kuka_openhand_description/meshes/allsight/allsight_fine01.obj"/>
      </geometry>
      <material name="white">
        <color rgba=".9 .9 .9 1"/>
      </material>
    </visual>
    <collision>
      <geometry>
        <mesh filename="../../urdf/kuka_openhand_description/meshes/allsight/allsight_fine01.obj"/>
      </geometry>
    </collision>
  </link>

  <link name="finger_2_1">
        <contact>
        <lateral_friction value="1"/>
        <rolling_friction value="0.1"/>
        <contact_cfm value="0.0"/>
        <contact_erp value="1.0"/>
      </contact>
    <inertial>
      <origin rpy="0 0 0" xyz="0 0 0"/>
      <mass value="0.1"/>
      <inertia ixx="0.001" ixy="0.0" ixz="0.0" iyy="0.001" iyz="0.0" izz="0.001"/>
    </inertial>
    <visual>
  <material name="coolgrey" >
    <color rgba="0.5843137254901961 0.6392156862745098 0.6509803921568628 1.0" />
  </material>
      <origin rpy="1.57079632679 3.14159265359 -1.57079632679" xyz="-0.00 0.0 0.00"/>
      <geometry>
        <mesh filename="../../urdf/kuka_openhand_description/meshes/yale_openhand_O/swivel_1.obj"/>
      </geometry>
    </visual>
    <collision>
      <origin rpy="0 1.57079632679 0 " xyz="0.00 0.0 0.00"/>
      <geometry>
        <cylinder length="0.002" radius="0.018"/>
      </geometry>
    </collision>
  </link>

  <link name="finger_2_2">
        <contact>
        <lateral_friction value="1"/>
        <rolling_friction value="0.1"/>
        <contact_cfm value="0.0"/>
        <contact_erp value="1.0"/>
      </contact>
    <inertial>
      <!--                  <origin xyz="-0.005 0.03 0" rpy="0 0 0"/>-->
      <origin rpy="0 0 0" xyz="0 0 0"/>
      <mass value="0.1"/>
      <inertia ixx="0.001" ixy="0.0" ixz="0.0" iyy="0.001" iyz="0.0" izz="0.001"/>
    </inertial>
    <visual>
  <material name="lightgrey" >
    <color rgba="0.8470588235294118 0.8627450980392157 0.8392156862745098 1.0" />
  </material>
      <origin rpy="0 -3.141592653592 2.4" xyz="-0.00 0.0753 0.008"/>
      <geometry>
        <mesh filename="../../urdf/kuka_openhand_description/meshes/yale_openhand_O/proximal_O.obj" scale="0.00100 0.00100 0.00100"/>
      </geometry>
    </visual>
    <collision>
      <origin rpy="0 -3.141592653592 2.4" xyz="-0.00 0.0753 0.008"/>
      <geometry>
        <mesh filename="../../urdf/kuka_openhand_description/meshes/yale_openhand_O/proximal_O.obj" scale="0.00100 0.00100 0.00100"/>
      </geometry>
    </collision>
  </link>

  <link name="finger_2_3">

      <inertial>
      <!--                  <origin xyz="-0.005 0.03 0" rpy="0 0 0"/>-->
      <origin rpy="0 0 0" xyz="0 0 0"/>
      <mass value="0.1"/>
      <inertia ixx="0.001" ixy="0.0" ixz="0.0" iyy="0.001" iyz="0.0" izz="0.001"/>
    </inertial>
    <visual>
      <geometry>
        <mesh filename="../../urdf/kuka_openhand_description/meshes/allsight/allsight_fine01.obj"/>
      </geometry>
      <material name="white">
        <color rgba=".9 .9 .9 1"/>
      </material>
    </visual>
    <collision>
      <geometry>
        <mesh filename="../../urdf/kuka_openhand_description/meshes/allsight/allsight_fine01.obj"/>
      </geometry>
    </collision>
  </link>

  <link name="finger_3_2">
        <contact>
        <lateral_friction value="1"/>
        <rolling_friction value="0.1"/>
        <contact_cfm value="0.0"/>
        <contact_erp value="1.0"/>
      </contact>
    <inertial>
      <!--                  <origin xyz="-0.005 0.03 0" rpy="0 0 0"/>-->
      <origin rpy="0 0 0" xyz="0 0 0"/>
      <mass value="0.1"/>
      <inertia ixx="0.001" ixy="0.0" ixz="0.0" iyy="0.001" iyz="0.0" izz="0.001"/>
    </inertial>
    <visual>
  <material name="lightgrey" >
    <color rgba="0.8470588235294118 0.8627450980392157 0.8392156862745098 1.0" />
  </material>
      <origin rpy="0 -3.141592653592 2.4" xyz="-0.00 0.0753 0.008"/>
      <geometry>
        <mesh filename="../../urdf/kuka_openhand_description/meshes/yale_openhand_O/proximal_O.obj" scale="0.00100 0.00100 0.00100"/>
      </geometry>
    </visual>
    <collision>
      <origin rpy="0 -3.141592653592 2.4" xyz="-0.00 0.0753 0.008"/>
      <geometry>
        <mesh filename="../../urdf/kuka_openhand_description/meshes/yale_openhand_O/proximal_O.obj" scale="0.00100 0.00100 0.00100"/>
      </geometry>
    </collision>
  </link>

  <link name="finger_3_3">

      <inertial>
      <origin rpy="0 0 0" xyz="0 0 0"/>
      <mass value="0.1"/>
      <inertia ixx="0.001" ixy="0.0" ixz="0.0" iyy="0.001" iyz="0.0" izz="0.001"/>
    </inertial>
    <visual>
      <geometry>
        <mesh filename="../../urdf/kuka_openhand_description/meshes/allsight/allsight_fine01.obj"/>
      </geometry>
      <material name="white">
        <color rgba=".9 .9 .9 1"/>
      </material>
    </visual>
    <collision>
      <geometry>
        <mesh filename="../../urdf/kuka_openhand_description/meshes/allsight/allsight_fine01.obj"/>
      </geometry>
    </collision>
  </link>

  <!-- Joints -->

  <joint name="base_to_finger_1_1" type="revolute">
    <origin rpy="3.14159265359 0 0" xyz="-0.003 -0.034 -0.027"/>
    <parent link="gripper_base_link"/>
    <child link="finger_1_1"/>
    <limit effort="100" lower="0" upper="1.57079632679" velocity="2"/>
    <axis xyz="1 0 0"/>
    <dynamics friction="10" damping="10" />
  </joint>

  <joint name="finger_1_1_to_finger_1_2" type="revolute">
    <origin rpy="0 0 0" xyz="-0.02 0.00725 0"/>
    <parent link="finger_1_1"/>
    <child link="finger_1_2"/>
    <limit effort="100" lower="-0.1" upper="3.0" velocity="2"/>
    <axis xyz="0 0 1"/>
    <dynamics friction="10" damping="10" />
  </joint>

   <joint name="finger_1_2_to_finger_1_3" type="revolute">
    <origin rpy="1.57079632679 0 1.57079632679" xyz="0.000800 0.072 0"/>
    <parent link="finger_1_2"/>
    <child link="finger_1_3"/>
    <limit effort="100" lower="0.0" upper="1.27" velocity="2"/>
    <axis xyz="0 1 0"/>
    <dynamics friction="10" damping="10" />
  </joint>

  <joint name="base_to_finger_2_1" type="revolute">
    <origin rpy="3.14159265359 0 0" xyz="-0.003 -0.034 0.027"/>
    <parent link="gripper_base_link"/>
    <child link="finger_2_1"/>
    <limit effort="100" lower="-1.57079632679" upper="0" velocity="2"/>
    <axis xyz="1 0 0"/>
    <dynamics friction="10" damping="10" />
  </joint>

  <joint name="finger_2_1_to_finger_2_2" type="revolute">
    <origin rpy="0 0 0" xyz="-0.02 0.00725 0"/>
    <parent link="finger_2_1"/>
    <child link="finger_2_2"/>
    <limit effort="100" lower="-0.1" upper="3.0" velocity="2"/>
    <axis xyz="0 0 1"/>
    <dynamics friction="10" damping="10" />
  </joint>

      <joint name="base_to_finger_3_2" type="revolute">
    <origin rpy="0 0 0" xyz="-0.023 0.045 0.000000"/>
    <parent link="gripper_base_link"/>
    <child link="finger_3_2"/>
    <limit effort="100" lower="-0.1" upper="3.0" velocity="2"/>
    <axis xyz="0 0 1"/>
    <dynamics friction="10" damping="10" />
  </joint>

  <joint name="finger_2_2_to_finger_2_3" type="revolute">
    <origin rpy="1.57079632679 0 1.57079632679" xyz="0.000800 0.072 0"/>
    <parent link="finger_2_2"/>
    <child link="finger_2_3"/>
    <limit effort="100" lower="0.0" upper="1.27" velocity="2"/>
    <axis xyz="0 1 0"/>
    <dynamics friction="10" damping="10" />
  </joint>

  <joint name="finger_3_2_to_finger_3_3" type="revolute">
    <origin rpy="1.57079632679 0 1.57079632679" xyz="0.000800 0.072 0"/>
    <parent link="finger_3_2"/>
    <child link="finger_3_3"/>
    <limit effort="100" lower="0.0" upper="1.27" velocity="2"/>
    <axis xyz="0 1 0"/>
    <dynamics friction="10" damping="10" />
  </joint>

     <!--Used for calculating pose and Jacobian.
    Joint connects hand to dummy link located at midpoint between bottoms of fingertips (when centered).-->

   <joint name="iiwa7_joint_ee" type="fixed">
    <parent link="gripper_base_link"/>
    <child link="kuka_fingertip_centered"/>
    <origin rpy="0 -1.57079632679 0" xyz="-0.12 -0.01 -0.000"/>
  </joint>

  <link name="kuka_fingertip_centered" />

</robot>
